Jul 14 18:25:08 identv nova-conductor.log:  2015-07-15 01:25:08.752 2455 ERROR oslo_messaging._drivers.common [req-58cf654f-4697-4402-b936-768e37a603bc ] ['Traceback (most recent call last):\n', '  File "/opt/pf9/nova/lib/python2.6/site-packages/oslo_messaging/rpc/dispatcher.py", line 142, in _dispatch_and_reply\n    executor_callback))\n', '  File "/opt/pf9/nova/lib/python2.6/site-packages/oslo_messaging/rpc/dispatcher.py", line 186, in _dispatch\n    executor_callback)\n', '  File "/opt/pf9/nova/lib/python2.6/site-packages/oslo_messaging/rpc/dispatcher.py", line 130, in _do_dispatch\n    result = func(ctxt, **new_args)\n', '  File "/opt/pf9/nova/lib/python2.6/site-packages/oslo_messaging/rpc/server.py", line 142, in inner\n    return func(*args, **kwargs)\n', '  File "/opt/pf9/nova/lib/python2.6/site-packages/nova/conductor/manager.py", line 325, in service_update\n    svc = self.db.service_update(context, service[\'id\'], values)\n', '  File "/opt/pf9/nova/lib/python2.6/site-packages/nova/db/api.py", line 150, in service_update\n    return IMPL.service_update(context, service_id, values)\n', '  File "/opt/pf9/nova/lib/python2.6/site-packages/nova/db/sqlalchemy/api.py", line 129, in wrapper\n    return f(*args, **kwargs)\n', '  File "/opt/pf9/nova/lib/python2.6/site-packages/nova/db/sqlalchemy/api.py", line 185, in wrapped\n    return f(*args, **kwargs)\n', '  File "/opt/pf9/nova/lib/python2.6/site-packages/nova/db/sqlalchemy/api.py", line 584, in service_update\n    with_compute_node=False, session=session)\n', '  File "/opt/pf9/nova/lib/python2.6/site-packages/nova/db/sqlalchemy/api.py", line 484, in _service_get\n    result = query.first()\n', '  File "/opt/pf9/nova/lib/python2.6/site-packages/sqlalchemy/orm/query.py", line 2367, in first\n    ret = list(self[0:1])\n', '  File "/opt/pf9/nova/lib/python2.6/site-packages/sqlalchemy/orm/query.py", line 2228, in __getitem__\n    return list(res)\n', '  File "/opt/pf9/nova/lib/python2.6/site-packages/sqlalchemy/orm/query.py", line 2438, in __iter__\n    return self._execute_and_instances(context)\n', '  File "/opt/pf9/nova/lib/python2.6/site-packages/sqlalchemy/orm/query.py", line 2451, in _execute_and_instances\n    close_with_result=True)\n', '  File "/opt/pf9/nova/lib/python2.6/site-packages/sqlalchemy/orm/query.py", line 2442, in _connection_from_session\n    **kw)\n', '  File "/opt/pf9/nova/lib/python2.6/site-packages/sqlalchemy/orm/session.py", line 854, in connection\n    close_with_result=close_with_result)\n', '  File "/opt/pf9/nova/lib/python2.6/site-packages/sqlalchemy/orm/session.py", line 858, in _connection_for_bind\n    return self.transaction._connection_for_bind(engine)\n', '  File "/opt/pf9/nova/lib/python2.6/site-packages/sqlalchemy/orm/session.py", line 322, in _connection_for_bind\n    conn = bind.contextual_connect()\n', '  File "/opt/pf9/nova/lib/python2.6/site-packages/sqlalchemy/engine/base.py", line 1798, in contextual_connect\n    self.pool.connect(),\n', '  File "/opt/pf9/nova/lib/python2.6/site-packages/sqlalchemy/pool.py", line 338, in connect\n    return _ConnectionFairy._checkout(self)\n', '  File "/opt/pf9/nova/lib/python2.6/site-packages/sqlalchemy/pool.py", line 644, in _checkout\n    fairy = _ConnectionRecord.checkout(pool)\n', '  File "/opt/pf9/nova/lib/python2.6/site-packages/sqlalchemy/pool.py", line 440, in checkout\n    rec = pool._do_get()\n', '  File "/opt/pf9/nova/lib/python2.6/site-packages/sqlalchemy/pool.py", line 959, in _do_get\n    (self.size(), self.overflow(), self._timeout))\n', 'TimeoutError: QueuePool limit of size 5 overflow 10 reached, connection timed out, timeout 30\n']
Jul 14 18:25:21 identv nova-network.log:  2015-07-15 01:25:21.745 2478 ERROR oslo_messaging._drivers.common [req-171650a3-b590-4e0a-92a3-966dd8e7acac ] ['Traceback (most recent call last):\n', '  File "/opt/pf9/nova/lib/python2.6/site-packages/oslo_messaging/rpc/dispatcher.py", line 142, in _dispatch_and_reply\n    executor_callback))\n', '  File "/opt/pf9/nova/lib/python2.6/site-packages/oslo_messaging/rpc/dispatcher.py", line 186, in _dispatch\n    executor_callback)\n', '  File "/opt/pf9/nova/lib/python2.6/site-packages/oslo_messaging/rpc/dispatcher.py", line 130, in _do_dispatch\n    result = func(ctxt, **new_args)\n', '  File "/opt/pf9/nova/lib/python2.6/site-packages/oslo_messaging/rpc/server.py", line 142, in inner\n    return func(*args, **kwargs)\n', '  File "/opt/pf9/nova/lib/python2.6/site-packages/nova/network/manager.py", line 626, in get_instance_nw_info\n    rxtx_factor, host)\n', '  File "/opt/pf9/nova/lib/python2.6/site-packages/nova/network/manager.py", line 661, in build_network_info_model\n    network[\'project_id\'])\n', '  File "/opt/pf9/nova/lib/python2.6/site-packages/nova/network/nova_ipam_lib.py", line 86, in get_v4_ips_by_interface\n    vif_rec = objects.VirtualInterface.get_by_uuid(context, vif_id)\n', '  File "/opt/pf9/nova/lib/python2.6/site-packages/nova/objects/base.py", line 153, in wrapper\n    args, kwargs)\n', '  File "/opt/pf9/nova/lib/python2.6/site-packages/nova/conductor/rpcapi.py", line 372, in object_class_action\n    objver=objver, args=args, kwargs=kwargs)\n', '  File "/opt/pf9/nova/lib/python2.6/site-packages/oslo_messaging/rpc/client.py", line 156, in call\n    retry=self.retry)\n', '  File "/opt/pf9/nova/lib/python2.6/site-packages/oslo_messaging/transport.py", line 90, in _send\n    timeout=timeout, retry=retry)\n', '  File "/opt/pf9/nova/lib/python2.6/site-packages/oslo_messaging/_drivers/amqpdriver.py", line 417, in send\n    retry=retry)\n', '  File "/opt/pf9/nova/lib/python2.6/site-packages/oslo_messaging/_drivers/amqpdriver.py", line 406, in _send\n    result = self._waiter.wait(msg_id, timeout)\n', '  File "/opt/pf9/nova/lib/python2.6/site-packages/oslo_messaging/_drivers/amqpdriver.py", line 309, in wait\n    reply, ending, trylock = self._poll_queue(msg_id, timer)\n', '  File "/opt/pf9/nova/lib/python2.6/site-packages/oslo_messaging/_drivers/amqpdriver.py", line 247, in _poll_queue\n    message = self.waiters.get(msg_id, timeout=timeout)\n', '  File "/opt/pf9/nova/lib/python2.6/site-packages/oslo_messaging/_drivers/amqpdriver.py", line 148, in get\n    \'to message ID %s\' % msg_id)\n', 'MessagingTimeout: Timed out waiting for a reply to message ID 9232422bcc8c42e6ad5b7ba731372de6\n']
Jul 14 18:25:29 identv nova-network.log:  2015-07-15 01:25:29.828 2478 ERROR oslo_messaging._drivers.common [req-caecade5-b1c5-4fb1-b163-bafab2c06c36 ] ['Traceback (most recent call last):\n', '  File "/opt/pf9/nova/lib/python2.6/site-packages/oslo_messaging/rpc/dispatcher.py", line 142, in _dispatch_and_reply\n    executor_callback))\n', '  File "/opt/pf9/nova/lib/python2.6/site-packages/oslo_messaging/rpc/dispatcher.py", line 186, in _dispatch\n    executor_callback)\n', '  File "/opt/pf9/nova/lib/python2.6/site-packages/oslo_messaging/rpc/dispatcher.py", line 130, in _do_dispatch\n    result = func(ctxt, **new_args)\n', '  File "/opt/pf9/nova/lib/python2.6/site-packages/oslo_messaging/rpc/server.py", line 142, in inner\n    return func(*args, **kwargs)\n', '  File "/opt/pf9/nova/lib/python2.6/site-packages/nova/network/manager.py", line 626, in get_instance_nw_info\n    rxtx_factor, host)\n', '  File "/opt/pf9/nova/lib/python2.6/site-packages/nova/network/manager.py", line 665, in build_network_info_model\n    network[\'project_id\'])\n', '  File "/opt/pf9/nova/lib/python2.6/site-packages/nova/network/nova_ipam_lib.py", line 98, in get_v6_ips_by_interface\n    network = objects.Network.get_by_uuid(admin_context, net_id)\n', '  File "/opt/pf9/nova/lib/python2.6/site-packages/nova/objects/base.py", line 153, in wrapper\n    args, kwargs)\n', '  File "/opt/pf9/nova/lib/python2.6/site-packages/nova/conductor/rpcapi.py", line 372, in object_class_action\n    objver=objver, args=args, kwargs=kwargs)\n', '  File "/opt/pf9/nova/lib/python2.6/site-packages/oslo_messaging/rpc/client.py", line 156, in call\n    retry=self.retry)\n', '  File "/opt/pf9/nova/lib/python2.6/site-packages/oslo_messaging/transport.py", line 90, in _send\n    timeout=timeout, retry=retry)\n', '  File "/opt/pf9/nova/lib/python2.6/site-packages/oslo_messaging/_drivers/amqpdriver.py", line 417, in send\n    retry=retry)\n', '  File "/opt/pf9/nova/lib/python2.6/site-packages/oslo_messaging/_drivers/amqpdriver.py", line 406, in _send\n    result = self._waiter.wait(msg_id, timeout)\n', '  File "/opt/pf9/nova/lib/python2.6/site-packages/oslo_messaging/_drivers/amqpdriver.py", line 296, in wait\n    reply, ending = self._poll_connection(msg_id, timer)\n', '  File "/opt/pf9/nova/lib/python2.6/site-packages/oslo_messaging/_drivers/amqpdriver.py", line 243, in _poll_connection\n    self._raise_timeout_exception(msg_id)\n', '  File "/opt/pf9/nova/lib/python2.6/site-packages/oslo_messaging/_drivers/amqpdriver.py", line 212, in _raise_timeout_exception\n    _(\'Timed out waiting for a reply to message ID %s.\') % msg_id)\n', 'MessagingTimeout: Timed out waiting for a reply to message ID 49e4198862b64f919d7418c7d0645bc4.\n']
Jul 14 18:25:30 identv nova-network.log:  2015-07-15 01:25:29.988 2478 TRACE nova.servicegroup.drivers.db Traceback (most recent call last):
Jul 14 18:25:37 identv nova-conductor.log:  2015-07-15 01:25:36.586 2455 ERROR oslo_messaging._drivers.common [req-0b2bdba1-d89e-455a-b3f2-05a77ad0c0a3 ] ['Traceback (most recent call last):\n', '  File "/opt/pf9/nova/lib/python2.6/site-packages/oslo_messaging/rpc/dispatcher.py", line 142, in _dispatch_and_reply\n    executor_callback))\n', '  File "/opt/pf9/nova/lib/python2.6/site-packages/oslo_messaging/rpc/dispatcher.py", line 186, in _dispatch\n    executor_callback)\n', '  File "/opt/pf9/nova/lib/python2.6/site-packages/oslo_messaging/rpc/dispatcher.py", line 130, in _do_dispatch\n    result = func(ctxt, **new_args)\n', '  File "/opt/pf9/nova/lib/python2.6/site-packages/oslo_messaging/rpc/server.py", line 142, in inner\n    return func(*args, **kwargs)\n', '  File "/opt/pf9/nova/lib/python2.6/site-packages/nova/conductor/manager.py", line 325, in service_update\n    svc = self.db.service_update(context, service[\'id\'], values)\n', '  File "/opt/pf9/nova/lib/python2.6/site-packages/nova/db/api.py", line 150, in service_update\n    return IMPL.service_update(context, service_id, values)\n', '  File "/opt/pf9/nova/lib/python2.6/site-packages/nova/db/sqlalchemy/api.py", line 129, in wrapper\n    return f(*args, **kwargs)\n', '  File "/opt/pf9/nova/lib/python2.6/site-packages/nova/db/sqlalchemy/api.py", line 185, in wrapped\n    return f(*args, **kwargs)\n', '  File "/opt/pf9/nova/lib/python2.6/site-packages/nova/db/sqlalchemy/api.py", line 584, in service_update\n    with_compute_node=False, session=session)\n', '  File "/opt/pf9/nova/lib/python2.6/site-packages/nova/db/sqlalchemy/api.py", line 484, in _service_get\n    result = query.first()\n', '  File "/opt/pf9/nova/lib/python2.6/site-packages/sqlalchemy/orm/query.py", line 2367, in first\n    ret = list(self[0:1])\n', '  File "/opt/pf9/nova/lib/python2.6/site-packages/sqlalchemy/orm/query.py", line 2228, in __getitem__\n    return list(res)\n', '  File "/opt/pf9/nova/lib/python2.6/site-packages/sqlalchemy/orm/query.py", line 2438, in __iter__\n    return self._execute_and_instances(context)\n', '  File "/opt/pf9/nova/lib/python2.6/site-packages/sqlalchemy/orm/query.py", line 2451, in _execute_and_instances\n    close_with_result=True)\n', '  File "/opt/pf9/nova/lib/python2.6/site-packages/sqlalchemy/orm/query.py", line 2442, in _connection_from_session\n    **kw)\n', '  File "/opt/pf9/nova/lib/python2.6/site-packages/sqlalchemy/orm/session.py", line 854, in connection\n    close_with_result=close_with_result)\n', '  File "/opt/pf9/nova/lib/python2.6/site-packages/sqlalchemy/orm/session.py", line 858, in _connection_for_bind\n    return self.transaction._connection_for_bind(engine)\n', '  File "/opt/pf9/nova/lib/python2.6/site-packages/sqlalchemy/orm/session.py", line 322, in _connection_for_bind\n    conn = bind.contextual_connect()\n', '  File "/opt/pf9/nova/lib/python2.6/site-packages/sqlalchemy/engine/base.py", line 1798, in contextual_connect\n    self.pool.connect(),\n', '  File "/opt/pf9/nova/lib/python2.6/site-packages/sqlalchemy/pool.py", line 338, in connect\n    return _ConnectionFairy._checkout(self)\n', '  File "/opt/pf9/nova/lib/python2.6/site-packages/sqlalchemy/pool.py", line 644, in _checkout\n    fairy = _ConnectionRecord.checkout(pool)\n', '  File "/opt/pf9/nova/lib/python2.6/site-packages/sqlalchemy/pool.py", line 440, in checkout\n    rec = pool._do_get()\n', '  File "/opt/pf9/nova/lib/python2.6/site-packages/sqlalchemy/pool.py", line 959, in _do_get\n    (self.size(), self.overflow(), self._timeout))\n', 'TimeoutError: QueuePool limit of size 5 overflow 10 reached, connection timed out, timeout 30\n']
Jul 14 18:25:51 identv nova-conductor.log:  2015-07-15 01:25:51.438 2455 ERROR oslo_messaging._drivers.common [req-8abc3bc7-8171-45cb-9fc2-218b62b3c248 ] ['Traceback (most recent call last):\n', '  File "/opt/pf9/nova/lib/python2.6/site-packages/oslo_messaging/rpc/dispatcher.py", line 142, in _dispatch_and_reply\n    executor_callback))\n', '  File "/opt/pf9/nova/lib/python2.6/site-packages/oslo_messaging/rpc/dispatcher.py", line 186, in _dispatch\n    executor_callback)\n', '  File "/opt/pf9/nova/lib/python2.6/site-packages/oslo_messaging/rpc/dispatcher.py", line 130, in _do_dispatch\n    result = func(ctxt, **new_args)\n', '  File "/opt/pf9/nova/lib/python2.6/site-packages/oslo_messaging/rpc/server.py", line 142, in inner\n    return func(*args, **kwargs)\n', '  File "/opt/pf9/nova/lib/python2.6/site-packages/nova/conductor/manager.py", line 325, in service_update\n    svc = self.db.service_update(context, service[\'id\'], values)\n', '  File "/opt/pf9/nova/lib/python2.6/site-packages/nova/db/api.py", line 150, in service_update\n    return IMPL.service_update(context, service_id, values)\n', '  File "/opt/pf9/nova/lib/python2.6/site-packages/nova/db/sqlalchemy/api.py", line 129, in wrapper\n    return f(*args, **kwargs)\n', '  File "/opt/pf9/nova/lib/python2.6/site-packages/nova/db/sqlalchemy/api.py", line 185, in wrapped\n    return f(*args, **kwargs)\n', '  File "/opt/pf9/nova/lib/python2.6/site-packages/nova/db/sqlalchemy/api.py", line 584, in service_update\n    with_compute_node=False, session=session)\n', '  File "/opt/pf9/nova/lib/python2.6/site-packages/nova/db/sqlalchemy/api.py", line 484, in _service_get\n    result = query.first()\n', '  File "/opt/pf9/nova/lib/python2.6/site-packages/sqlalchemy/orm/query.py", line 2367, in first\n    ret = list(self[0:1])\n', '  File "/opt/pf9/nova/lib/python2.6/site-packages/sqlalchemy/orm/query.py", line 2228, in __getitem__\n    return list(res)\n', '  File "/opt/pf9/nova/lib/python2.6/site-packages/sqlalchemy/orm/query.py", line 2438, in __iter__\n    return self._execute_and_instances(context)\n', '  File "/opt/pf9/nova/lib/python2.6/site-packages/sqlalchemy/orm/query.py", line 2451, in _execute_and_instances\n    close_with_result=True)\n', '  File "/opt/pf9/nova/lib/python2.6/site-packages/sqlalchemy/orm/query.py", line 2442, in _connection_from_session\n    **kw)\n', '  File "/opt/pf9/nova/lib/python2.6/site-packages/sqlalchemy/orm/session.py", line 854, in connection\n    close_with_result=close_with_result)\n', '  File "/opt/pf9/nova/lib/python2.6/site-packages/sqlalchemy/orm/session.py", line 858, in _connection_for_bind\n    return self.transaction._connection_for_bind(engine)\n', '  File "/opt/pf9/nova/lib/python2.6/site-packages/sqlalchemy/orm/session.py", line 322, in _connection_for_bind\n    conn = bind.contextual_connect()\n', '  File "/opt/pf9/nova/lib/python2.6/site-packages/sqlalchemy/engine/base.py", line 1798, in contextual_connect\n    self.pool.connect(),\n', '  File "/opt/pf9/nova/lib/python2.6/site-packages/sqlalchemy/pool.py", line 338, in connect\n    return _ConnectionFairy._checkout(self)\n', '  File "/opt/pf9/nova/lib/python2.6/site-packages/sqlalchemy/pool.py", line 644, in _checkout\n    fairy = _ConnectionRecord.checkout(pool)\n', '  File "/opt/pf9/nova/lib/python2.6/site-packages/sqlalchemy/pool.py", line 440, in checkout\n    rec = pool._do_get()\n', '  File "/opt/pf9/nova/lib/python2.6/site-packages/sqlalchemy/pool.py", line 959, in _do_get\n    (self.size(), self.overflow(), self._timeout))\n', 'TimeoutError: QueuePool limit of size 5 overflow 10 reached, connection timed out, timeout 30\n']
Jul 14 18:25:51 identv nova-conductor.log:  2015-07-15 01:25:51.494 2455 ERROR oslo_messaging._drivers.common [req-0efc80ff-a10b-409a-a949-23b38bbcea81 ] ['Traceback (most recent call last):\n', '  File "/opt/pf9/nova/lib/python2.6/site-packages/oslo_messaging/rpc/dispatcher.py", line 142, in _dispatch_and_reply\n    executor_callback))\n', '  File "/opt/pf9/nova/lib/python2.6/site-packages/oslo_messaging/rpc/dispatcher.py", line 186, in _dispatch\n    executor_callback)\n', '  File "/opt/pf9/nova/lib/python2.6/site-packages/oslo_messaging/rpc/dispatcher.py", line 130, in _do_dispatch\n    result = func(ctxt, **new_args)\n', '  File "/opt/pf9/nova/lib/python2.6/site-packages/oslo_messaging/rpc/server.py", line 142, in inner\n    return func(*args, **kwargs)\n', '  File "/opt/pf9/nova/lib/python2.6/site-packages/nova/conductor/manager.py", line 325, in service_update\n    svc = self.db.service_update(context, service[\'id\'], values)\n', '  File "/opt/pf9/nova/lib/python2.6/site-packages/nova/db/api.py", line 150, in service_update\n    return IMPL.service_update(context, service_id, values)\n', '  File "/opt/pf9/nova/lib/python2.6/site-packages/nova/db/sqlalchemy/api.py", line 129, in wrapper\n    return f(*args, **kwargs)\n', '  File "/opt/pf9/nova/lib/python2.6/site-packages/nova/db/sqlalchemy/api.py", line 185, in wrapped\n    return f(*args, **kwargs)\n', '  File "/opt/pf9/nova/lib/python2.6/site-packages/nova/db/sqlalchemy/api.py", line 584, in service_update\n    with_compute_node=False, session=session)\n', '  File "/opt/pf9/nova/lib/python2.6/site-packages/nova/db/sqlalchemy/api.py", line 484, in _service_get\n    result = query.first()\n', '  File "/opt/pf9/nova/lib/python2.6/site-packages/sqlalchemy/orm/query.py", line 2367, in first\n    ret = list(self[0:1])\n', '  File "/opt/pf9/nova/lib/python2.6/site-packages/sqlalchemy/orm/query.py", line 2228, in __getitem__\n    return list(res)\n', '  File "/opt/pf9/nova/lib/python2.6/site-packages/sqlalchemy/orm/query.py", line 2438, in __iter__\n    return self._execute_and_instances(context)\n', '  File "/opt/pf9/nova/lib/python2.6/site-packages/sqlalchemy/orm/query.py", line 2451, in _execute_and_instances\n    close_with_result=True)\n', '  File "/opt/pf9/nova/lib/python2.6/site-packages/sqlalchemy/orm/query.py", line 2442, in _connection_from_session\n    **kw)\n', '  File "/opt/pf9/nova/lib/python2.6/site-packages/sqlalchemy/orm/session.py", line 854, in connection\n    close_with_result=close_with_result)\n', '  File "/opt/pf9/nova/lib/python2.6/site-packages/sqlalchemy/orm/session.py", line 858, in _connection_for_bind\n    return self.transaction._connection_for_bind(engine)\n', '  File "/opt/pf9/nova/lib/python2.6/site-packages/sqlalchemy/orm/session.py", line 322, in _connection_for_bind\n    conn = bind.contextual_connect()\n', '  File "/opt/pf9/nova/lib/python2.6/site-packages/sqlalchemy/engine/base.py", line 1798, in contextual_connect\n    self.pool.connect(),\n', '  File "/opt/pf9/nova/lib/python2.6/site-packages/sqlalchemy/pool.py", line 338, in connect\n    return _ConnectionFairy._checkout(self)\n', '  File "/opt/pf9/nova/lib/python2.6/site-packages/sqlalchemy/pool.py", line 644, in _checkout\n    fairy = _ConnectionRecord.checkout(pool)\n', '  File "/opt/pf9/nova/lib/python2.6/site-packages/sqlalchemy/pool.py", line 440, in checkout\n    rec = pool._do_get()\n', '  File "/opt/pf9/nova/lib/python2.6/site-packages/sqlalchemy/pool.py", line 959, in _do_get\n    (self.size(), self.overflow(), self._timeout))\n', 'TimeoutError: QueuePool limit of size 5 overflow 10 reached, connection timed out, timeout 30\n']
Jul 14 18:25:51 identv nova-conductor.log:  2015-07-15 01:25:51.547 2455 ERROR oslo_messaging._drivers.common [req-0dc19b75-87f5-428a-b604-fc4d02acb043 ] ['Traceback (most recent call last):\n', '  File "/opt/pf9/nova/lib/python2.6/site-packages/oslo_messaging/rpc/dispatcher.py", line 142, in _dispatch_and_reply\n    executor_callback))\n', '  File "/opt/pf9/nova/lib/python2.6/site-packages/oslo_messaging/rpc/dispatcher.py", line 186, in _dispatch\n    executor_callback)\n', '  File "/opt/pf9/nova/lib/python2.6/site-packages/oslo_messaging/rpc/dispatcher.py", line 130, in _do_dispatch\n    result = func(ctxt, **new_args)\n', '  File "/opt/pf9/nova/lib/python2.6/site-packages/oslo_messaging/rpc/server.py", line 142, in inner\n    return func(*args, **kwargs)\n', '  File "/opt/pf9/nova/lib/python2.6/site-packages/nova/conductor/manager.py", line 325, in service_update\n    svc = self.db.service_update(context, service[\'id\'], values)\n', '  File "/opt/pf9/nova/lib/python2.6/site-packages/nova/db/api.py", line 150, in service_update\n    return IMPL.service_update(context, service_id, values)\n', '  File "/opt/pf9/nova/lib/python2.6/site-packages/nova/db/sqlalchemy/api.py", line 129, in wrapper\n    return f(*args, **kwargs)\n', '  File "/opt/pf9/nova/lib/python2.6/site-packages/nova/db/sqlalchemy/api.py", line 185, in wrapped\n    return f(*args, **kwargs)\n', '  File "/opt/pf9/nova/lib/python2.6/site-packages/nova/db/sqlalchemy/api.py", line 584, in service_update\n    with_compute_node=False, session=session)\n', '  File "/opt/pf9/nova/lib/python2.6/site-packages/nova/db/sqlalchemy/api.py", line 484, in _service_get\n    result = query.first()\n', '  File "/opt/pf9/nova/lib/python2.6/site-packages/sqlalchemy/orm/query.py", line 2367, in first\n    ret = list(self[0:1])\n', '  File "/opt/pf9/nova/lib/python2.6/site-packages/sqlalchemy/orm/query.py", line 2228, in __getitem__\n    return list(res)\n', '  File "/opt/pf9/nova/lib/python2.6/site-packages/sqlalchemy/orm/query.py", line 2438, in __iter__\n    return self._execute_and_instances(context)\n', '  File "/opt/pf9/nova/lib/python2.6/site-packages/sqlalchemy/orm/query.py", line 2451, in _execute_and_instances\n    close_with_result=True)\n', '  File "/opt/pf9/nova/lib/python2.6/site-packages/sqlalchemy/orm/query.py", line 2442, in _connection_from_session\n    **kw)\n', '  File "/opt/pf9/nova/lib/python2.6/site-packages/sqlalchemy/orm/session.py", line 854, in connection\n    close_with_result=close_with_result)\n', '  File "/opt/pf9/nova/lib/python2.6/site-packages/sqlalchemy/orm/session.py", line 858, in _connection_for_bind\n    return self.transaction._connection_for_bind(engine)\n', '  File "/opt/pf9/nova/lib/python2.6/site-packages/sqlalchemy/orm/session.py", line 322, in _connection_for_bind\n    conn = bind.contextual_connect()\n', '  File "/opt/pf9/nova/lib/python2.6/site-packages/sqlalchemy/engine/base.py", line 1798, in contextual_connect\n    self.pool.connect(),\n', '  File "/opt/pf9/nova/lib/python2.6/site-packages/sqlalchemy/pool.py", line 338, in connect\n    return _ConnectionFairy._checkout(self)\n', '  File "/opt/pf9/nova/lib/python2.6/site-packages/sqlalchemy/pool.py", line 644, in _checkout\n    fairy = _ConnectionRecord.checkout(pool)\n', '  File "/opt/pf9/nova/lib/python2.6/site-packages/sqlalchemy/pool.py", line 440, in checkout\n    rec = pool._do_get()\n', '  File "/opt/pf9/nova/lib/python2.6/site-packages/sqlalchemy/pool.py", line 959, in _do_get\n    (self.size(), self.overflow(), self._timeout))\n', 'TimeoutError: QueuePool limit of size 5 overflow 10 reached, connection timed out, timeout 30\n']
Jul 14 18:25:51 identv nova-conductor.log:  2015-07-15 01:25:51.674 2455 ERROR oslo_messaging._drivers.common [req-7d1fb5d2-936c-46b8-bdc7-4895e51dd0ff ] ['Traceback (most recent call last):\n', '  File "/opt/pf9/nova/lib/python2.6/site-packages/oslo_messaging/rpc/dispatcher.py", line 142, in _dispatch_and_reply\n    executor_callback))\n', '  File "/opt/pf9/nova/lib/python2.6/site-packages/oslo_messaging/rpc/dispatcher.py", line 186, in _dispatch\n    executor_callback)\n', '  File "/opt/pf9/nova/lib/python2.6/site-packages/oslo_messaging/rpc/dispatcher.py", line 130, in _do_dispatch\n    result = func(ctxt, **new_args)\n', '  File "/opt/pf9/nova/lib/python2.6/site-packages/oslo_messaging/rpc/server.py", line 142, in inner\n    return func(*args, **kwargs)\n', '  File "/opt/pf9/nova/lib/python2.6/site-packages/nova/conductor/manager.py", line 325, in service_update\n    svc = self.db.service_update(context, service[\'id\'], values)\n', '  File "/opt/pf9/nova/lib/python2.6/site-packages/nova/db/api.py", line 150, in service_update\n    return IMPL.service_update(context, service_id, values)\n', '  File "/opt/pf9/nova/lib/python2.6/site-packages/nova/db/sqlalchemy/api.py", line 129, in wrapper\n    return f(*args, **kwargs)\n', '  File "/opt/pf9/nova/lib/python2.6/site-packages/nova/db/sqlalchemy/api.py", line 185, in wrapped\n    return f(*args, **kwargs)\n', '  File "/opt/pf9/nova/lib/python2.6/site-packages/nova/db/sqlalchemy/api.py", line 584, in service_update\n    with_compute_node=False, session=session)\n', '  File "/opt/pf9/nova/lib/python2.6/site-packages/nova/db/sqlalchemy/api.py", line 484, in _service_get\n    result = query.first()\n', '  File "/opt/pf9/nova/lib/python2.6/site-packages/sqlalchemy/orm/query.py", line 2367, in first\n    ret = list(self[0:1])\n', '  File "/opt/pf9/nova/lib/python2.6/site-packages/sqlalchemy/orm/query.py", line 2228, in __getitem__\n    return list(res)\n', '  File "/opt/pf9/nova/lib/python2.6/site-packages/sqlalchemy/orm/query.py", line 2438, in __iter__\n    return self._execute_and_instances(context)\n', '  File "/opt/pf9/nova/lib/python2.6/site-packages/sqlalchemy/orm/query.py", line 2451, in _execute_and_instances\n    close_with_result=True)\n', '  File "/opt/pf9/nova/lib/python2.6/site-packages/sqlalchemy/orm/query.py", line 2442, in _connection_from_session\n    **kw)\n', '  File "/opt/pf9/nova/lib/python2.6/site-packages/sqlalchemy/orm/session.py", line 854, in connection\n    close_with_result=close_with_result)\n', '  File "/opt/pf9/nova/lib/python2.6/site-packages/sqlalchemy/orm/session.py", line 858, in _connection_for_bind\n    return self.transaction._connection_for_bind(engine)\n', '  File "/opt/pf9/nova/lib/python2.6/site-packages/sqlalchemy/orm/session.py", line 322, in _connection_for_bind\n    conn = bind.contextual_connect()\n', '  File "/opt/pf9/nova/lib/python2.6/site-packages/sqlalchemy/engine/base.py", line 1798, in contextual_connect\n    self.pool.connect(),\n', '  File "/opt/pf9/nova/lib/python2.6/site-packages/sqlalchemy/pool.py", line 338, in connect\n    return _ConnectionFairy._checkout(self)\n', '  File "/opt/pf9/nova/lib/python2.6/site-packages/sqlalchemy/pool.py", line 644, in _checkout\n    fairy = _ConnectionRecord.checkout(pool)\n', '  File "/opt/pf9/nova/lib/python2.6/site-packages/sqlalchemy/pool.py", line 440, in checkout\n    rec = pool._do_get()\n', '  File "/opt/pf9/nova/lib/python2.6/site-packages/sqlalchemy/pool.py", line 959, in _do_get\n    (self.size(), self.overflow(), self._timeout))\n', 'TimeoutError: QueuePool limit of size 5 overflow 10 reached, connection timed out, timeout 30\n']
Jul 14 18:27:54 identv nova-conductor.log:  2015-07-15 01:27:54.764 2455 ERROR oslo_messaging._drivers.common [req-f40ff596-1f1f-4763-a118-845553048cea ] ['Traceback (most recent call last):\n', '  File "/opt/pf9/nova/lib/python2.6/site-packages/oslo_messaging/rpc/dispatcher.py", line 142, in _dispatch_and_reply\n    executor_callback))\n', '  File "/opt/pf9/nova/lib/python2.6/site-packages/oslo_messaging/rpc/dispatcher.py", line 186, in _dispatch\n    executor_callback)\n', '  File "/opt/pf9/nova/lib/python2.6/site-packages/oslo_messaging/rpc/dispatcher.py", line 130, in _do_dispatch\n    result = func(ctxt, **new_args)\n', '  File "/opt/pf9/nova/lib/python2.6/site-packages/nova/conductor/manager.py", line 155, in migration_get_in_progress_by_host_and_node\n    context, host, node)\n', '  File "/opt/pf9/nova/lib/python2.6/site-packages/nova/db/api.py", line 501, in migration_get_in_progress_by_host_and_node\n    return IMPL.migration_get_in_progress_by_host_and_node(context, host, node)\n', '  File "/opt/pf9/nova/lib/python2.6/site-packages/nova/db/sqlalchemy/api.py", line 129, in wrapper\n    return f(*args, **kwargs)\n', '  File "/opt/pf9/nova/lib/python2.6/site-packages/nova/db/sqlalchemy/api.py", line 5218, in migration_get_in_progress_by_host_and_node\n    options(joinedload_all(\'instance.system_metadata\')).\\\n', '  File "/opt/pf9/nova/lib/python2.6/site-packages/sqlalchemy/orm/query.py", line 2320, in all\n    return list(self)\n', '  File "/opt/pf9/nova/lib/python2.6/site-packages/sqlalchemy/orm/query.py", line 2438, in __iter__\n    return self._execute_and_instances(context)\n', '  File "/opt/pf9/nova/lib/python2.6/site-packages/sqlalchemy/orm/query.py", line 2451, in _execute_and_instances\n    close_with_result=True)\n', '  File "/opt/pf9/nova/lib/python2.6/site-packages/sqlalchemy/orm/query.py", line 2442, in _connection_from_session\n    **kw)\n', '  File "/opt/pf9/nova/lib/python2.6/site-packages/sqlalchemy/orm/session.py", line 854, in connection\n    close_with_result=close_with_result)\n', '  File "/opt/pf9/nova/lib/python2.6/site-packages/sqlalchemy/orm/session.py", line 860, in _connection_for_bind\n    return engine.contextual_connect(**kwargs)\n', '  File "/opt/pf9/nova/lib/python2.6/site-packages/sqlalchemy/engine/base.py", line 1798, in contextual_connect\n    self.pool.connect(),\n', '  File "/opt/pf9/nova/lib/python2.6/site-packages/sqlalchemy/pool.py", line 338, in connect\n    return _ConnectionFairy._checkout(self)\n', '  File "/opt/pf9/nova/lib/python2.6/site-packages/sqlalchemy/pool.py", line 644, in _checkout\n    fairy = _ConnectionRecord.checkout(pool)\n', '  File "/opt/pf9/nova/lib/python2.6/site-packages/sqlalchemy/pool.py", line 440, in checkout\n    rec = pool._do_get()\n', '  File "/opt/pf9/nova/lib/python2.6/site-packages/sqlalchemy/pool.py", line 959, in _do_get\n    (self.size(), self.overflow(), self._timeout))\n', 'TimeoutError: QueuePool limit of size 5 overflow 10 reached, connection timed out, timeout 30\n']
