{
  "data" : [{\"Message\":\"2016-11-25 23:29:47.259 ERROR oslo.messaging._drivers.impl_rabbit [req-5dd44ea2-22d3-4830-8362-74c704594753 None None] AMQP server on __nova_controller_host__:5673 is unreachable: [Errno -2] Name or service not known. Trying again in 32 seconds.\",\"Time\":1480116587259,\"Host\":\"pf9-aws-hybrid-dev.platform9.net\",\"Category\":\"prod\/openstack\/nova\",\"Name\":\"\/var\/log\/nova\/nova-compute.log\",\"Collector\":\"pf9-aws-hybrid-dev.platform9.net\"},{\"Message\":\"2016-11-25 23:29:46.975 ERROR oslo.messaging._drivers.impl_rabbit [req-08b39e22-41da-499b-92cf-f6115841a14a None None] AMQP server on __nova_controller_host__:5673 is unreachable: [Errno -2] Name or service not known. Trying again in 32 seconds.\",\"Time\":1480116586975,\"Host\":\"pf9-aws-platform9.platform9.net\",\"Category\":\"prod\/openstack\/nova\",\"Name\":\"\/var\/log\/nova\/nova-compute.log\",\"Collector\":\"pf9-aws-platform9.platform9.net\"},{\"Message\":\"2016-11-25 23:29:20.588 12242 ERROR oslo_messaging._drivers.common [req-7709e54a-5b88-4911-813d-68caabd49e3d b412122e1bae40b2b0f41b9bb4c95e21 d27a645d8cac4eeb8c85bce799f7609d - - -] ['Traceback (most recent call last):\\\\n', '  File \\\"\/opt\/pf9\/nova\/lib\/python2.7\/site-packages\/oslo_messaging\/rpc\/dispatcher.py\\\", line 138, in _dispatch_and_reply\\\\n    incoming.message))\\\\n', '  File \\\"\/opt\/pf9\/nova\/lib\/python2.7\/site-packages\/oslo_messaging\/rpc\/dispatcher.py\\\", line 183, in _dispatch\\\\n    return self._do_dispatch(endpoint, method, ctxt, args)\\\\n', '  File \\\"\/opt\/pf9\/nova\/lib\/python2.7\/site-packages\/oslo_messaging\/rpc\/dispatcher.py\\\", line 127, in _do_dispatch\\\\n    result = func(ctxt, **new_args)\\\\n', '  File \\\"\/opt\/pf9\/nova\/lib\/python2.7\/site-packages\/nova\/network\/manager.py\\\", line 2041, in delete_network\\\\n    network.destroy()\\\\n', '  File \\\"\/opt\/pf9\/nova\/lib\/python2.7\/site-packages\/oslo_versionedobjects\/base.py\\\", line 207, in wrapper\\\\n    ctxt, self, fn.__name__, args, kwargs)\\\\n', '  File \\\"\/opt\/pf9\/nova\/lib\/python2.7\/site-packages\/nova\/conductor\/rpcapi.py\\\", line 273, in object_action\\\\n    objmethod=objmethod, args=args, kwargs=kwargs)\\\\n', '  File \\\"\/opt\/pf9\/nova\/lib\/python2.7\/site-packages\/oslo_messaging\/rpc\/client.py\\\", line 158, in call\\\\n    retry=self.retry)\\\\n', '  File \\\"\/opt\/pf9\/nova\/lib\/python2.7\/site-packages\/oslo_messaging\/transport.py\\\", line 90, in _send\\\\n    timeout=timeout, retry=retry)\\\\n', '  File \\\"\/opt\/pf9\/nova\/lib\/python2.7\/site-packages\/oslo_messaging\/_drivers\/amqpdriver.py\\\", line 470, in send\\\\n    retry=retry)\\\\n', '  File \\\"\/opt\/pf9\/nova\/lib\/python2.7\/site-packages\/oslo_messaging\/_drivers\/amqpdriver.py\\\", line 461, in _send\\\\n    raise result\\\\n', 'NetworkInUse_Remote: Network 5 is still in use.\\\\nTraceback (most recent call last):\\\\n\\\\n  File \\\"\/opt\/pf9\/nova\/lib\/python2.7\/site-packages\/nova\/conductor\/manager.py\\\", line 457, in _object_dispatch\\\\n    return getattr(target, method)(*args, **kwargs)\\\\n\\\\n  File \\\"\/opt\/pf9\/nova\/lib\/python2.7\/site-packages\/oslo_versionedobjects\/base.py\\\", line 223, in wrapper\\\\n    return fn(self, *args, **kwargs)\\\\n\\\\n  File \\\"\/opt\/pf9\/nova\/lib\/python2.7\/site-packages\/nova\/objects\/network.py\\\", line 187, in destroy\\\\n    db.network_delete_safe(self._context, self.id)\\\\n\\\\n  File \\\"\/opt\/pf9\/nova\/lib\/python2.7\/site-packages\/nova\/db\/api.py\\\", line 1024, in network_delete_safe\\\\n    return IMPL.network_delete_safe(context, network_id)\\\\n\\\\n  File \\\"\/opt\/pf9\/nova\/lib\/python2.7\/site-packages\/nova\/db\/sqlalchemy\/api.py\\\", line 3536, in network_delete_safe\\\\n    raise exception.NetworkInUse(network_id=network_id)\\\\n\\\\nNetworkInUse: Network 5 is still in use.\\\\n\\\\n']\",\"Time\":1480116560588,\"Host\":\"pf9.platform9.net\",\"Category\":\"prod\/openstack\/nova\",\"Name\":\"\/var\/log\/nova\/nova-network.log\",\"Collector\":\"pf9.platform9.net\"},{\"Message\":\"2016-11-25 23:29:20.588 12242 ERROR oslo_messaging._drivers.common [req-7709e54a-5b88-4911-813d-68caabd49e3d b412122e1bae40b2b0f41b9bb4c95e21 d27a645d8cac4eeb8c85bce799f7609d - - -] Returning exception Network 5 is still in use.\\nTraceback (most recent call last):\\n  File \\\"\/opt\/pf9\/nova\/lib\/python2.7\/site-packages\/nova\/conductor\/manager.py\\\", line 457, in _object_dispatch\\n    return getattr(target, method)(*args, **kwargs)\\n  File \\\"\/opt\/pf9\/nova\/lib\/python2.7\/site-packages\/oslo_versionedobjects\/base.py\\\", line 223, in wrapper\\n    return fn(self, *args, **kwargs)\\n  File \\\"\/opt\/pf9\/nova\/lib\/python2.7\/site-packages\/nova\/objects\/network.py\\\", line 187, in destroy\\n    db.network_delete_safe(self._context, self.id)\\n  File \\\"\/opt\/pf9\/nova\/lib\/python2.7\/site-packages\/nova\/db\/api.py\\\", line 1024, in network_delete_safe\\n    return IMPL.network_delete_safe(context, network_id)\\n  File \\\"\/opt\/pf9\/nova\/lib\/python2.7\/site-packages\/nova\/db\/sqlalchemy\/api.py\\\", line 3536, in network_delete_safe\\n    raise exception.NetworkInUse(network_id=network_id)\\nNetworkInUse: Network 5 is still in use.\\n to caller\",\"Time\":1480116560588,\"Host\":\"pf9.platform9.net\",\"Category\":\"prod\/openstack\/nova\",\"Name\":\"\/var\/log\/nova\/nova-network.log\",\"Collector\":\"pf9.platform9.net\"},{\"Message\":\"2016-11-25 23:29:20.586 12242 ERROR oslo_messaging.rpc.dispatcher \",\"Time\":1480116560586,\"Host\":\"pf9.platform9.net\",\"Category\":\"prod\/openstack\/nova\",\"Name\":\"\/var\/log\/nova\/nova-network.log\",\"Collector\":\"pf9.platform9.net\"},{\"Message\":\"2016-11-25 23:29:20.586 12242 ERROR oslo_messaging.rpc.dispatcher \",\"Time\":1480116560586,\"Host\":\"pf9.platform9.net\",\"Category\":\"prod\/openstack\/nova\",\"Name\":\"\/var\/log\/nova\/nova-network.log\",\"Collector\":\"pf9.platform9.net\"},{\"Message\":\"2016-11-25 23:29:20.586 12242 ERROR oslo_messaging.rpc.dispatcher NetworkInUse: Network 5 is still in use.\",\"Time\":1480116560586,\"Host\":\"pf9.platform9.net\",\"Category\":\"prod\/openstack\/nova\",\"Name\":\"\/var\/log\/nova\/nova-network.log\",\"Collector\":\"pf9.platform9.net\"},{\"Message\":\"2016-11-25 23:29:20.586 12242 ERROR oslo_messaging.rpc.dispatcher \",\"Time\":1480116560586,\"Host\":\"pf9.platform9.net\",\"Category\":\"prod\/openstack\/nova\",\"Name\":\"\/var\/log\/nova\/nova-network.log\",\"Collector\":\"pf9.platform9.net\"},{\"Message\":\"2016-11-25 23:29:20.586 12242 ERROR oslo_messaging.rpc.dispatcher     raise exception.NetworkInUse(network_id=network_id)\",\"Time\":1480116560586,\"Host\":\"pf9.platform9.net\",\"Category\":\"prod\/openstack\/nova\",\"Name\":\"\/var\/log\/nova\/nova-network.log\",\"Collector\":\"pf9.platform9.net\"},{\"Message\":\"2016-11-25 23:29:20.586 12242 ERROR oslo_messaging.rpc.dispatcher   File \\\"\/opt\/pf9\/nova\/lib\/python2.7\/site-packages\/nova\/db\/sqlalchemy\/api.py\\\", line 3536, in network_delete_safe\",\"Time\":1480116560586,\"Host\":\"pf9.platform9.net\",\"Category\":\"prod\/openstack\/nova\",\"Name\":\"\/var\/log\/nova\/nova-network.log\",\"Collector\":\"pf9.platform9.net\"},
  {\"Message\":\"2016-11-24 18:14:36.755 ERROR oslo.messaging._drivers.impl_rabbit [req-08b39e22-41da-499b-92cf-f6115841a14a None None] AMQP server on __nova_controller_host__:5673 is unreachable: [Errno -2] Name or service not known. Trying again in 32 seconds.\",\"Time\":1480011276755,\"Host\":\"pf9-aws-platform9.platform9.net\",\"Category\":\"prod\/openstack\/nova\",\"Name\":\"\/var\/log\/nova\/nova-compute.log\",\"Collector\":\"pf9-aws-platform9.platform9.net\"},
  {\"Message\":\"2016-11-24 18:14:36.755 ERROR oslo.messaging._drivers.impl_rabbit [req-08b39e22-41da-499b-92cf-f6115841a14a None None] AMQP server on __nova_controller_host__:5673 is unreachable: [Errno -2] Name or service not known. Trying again in 32 seconds.\",\"Time\":1480011276755,\"Host\":\"pf9-aws-platform9.platform9.net\",\"Category\":\"prod\/openstack\/nova\",\"Name\":\"\/var\/log\/nova\/nova-compute.log\",\"Collector\":\"pf9-aws-platform9.platform9.net\"},
  {\"Message\":\"2016-11-24 18:14:36.755 ERROR oslo.messaging._drivers.impl_rabbit [req-08b39e22-41da-499b-92cf-f6115841a14a None None] AMQP server on __nova_controller_host__:5673 is unreachable: [Errno -2] Name or service not known. Trying again in 32 seconds.\",\"Time\":1480011276755,\"Host\":\"pf9-aws-platform9.platform9.net\",\"Category\":\"prod\/openstack\/nova\",\"Name\":\"\/var\/log\/nova\/nova-compute.log\",\"Collector\":\"pf9-aws-platform9.platform9.net\"},
  {\"Message\":\"2016-11-24 18:14:36.755 ERROR oslo.messaging._drivers.impl_rabbit [req-08b39e22-41da-499b-92cf-f6115841a14a None None] AMQP server on __nova_controller_host__:5673 is unreachable: [Errno -2] Name or service not known. Trying again in 32 seconds.\",\"Time\":1480011276755,\"Host\":\"pf9-aws-platform9.platform9.net\",\"Category\":\"prod\/openstack\/nova\",\"Name\":\"\/var\/log\/nova\/nova-compute.log\",\"Collector\":\"pf9-aws-platform9.platform9.net\"},
  {\"Message\":\"2016-11-24 18:14:36.755 ERROR oslo.messaging._drivers.impl_rabbit [req-08b39e22-41da-499b-92cf-f6115841a14a None None] AMQP server on __nova_controller_host__:5673 is unreachable: [Errno -2] Name or service not known. Trying again in 32 seconds.\",\"Time\":1480011276755,\"Host\":\"pf9-aws-platform9.platform9.net\",\"Category\":\"prod\/openstack\/nova\",\"Name\":\"\/var\/log\/nova\/nova-compute.log\",\"Collector\":\"pf9-aws-platform9.platform9.net\"}]
}
